Time slot   0
ld_routine
Time slot   1
	Loaded a process at input/proc/p1s, PID: 1 PRIO: 15
Time slot   2
	CPU 3: Dispatched process  1
Time slot   3
	CPU 3: Put process  1 to run queue
	CPU 3: Dispatched process  1
Time slot   4
Time slot   5
	Loaded a process at input/proc/m0s, PID: 2 PRIO: 120
Time slot   6
	CPU 3: Put process  1 to run queue
	CPU 3: Dispatched process  1
	CPU 1: Dispatched process  2
print_pgtbl: 0 - -1
Time slot   7
print_pgtbl: 0 - -1	Loaded a process at input/proc/p0s, PID: 3 PRIO: 130

	CPU 3: Put process  1 to run queue
	CPU 3: Dispatched process  1
	CPU 1: Put process  2 to run queue
	CPU 1: Dispatched process  2
Time slot   8
	CPU 2: Dispatched process  3
libfree:205
print_pgtbl: 0 - -1
Time slot   9
print_pgtbl: 0 - -1print_pgtbl: 0 - -1	Loaded a process at input/proc/s0, PID: 4 PRIO: 38


	CPU 3: Put process  1 to run queue
	CPU 3: Dispatched process  1
	CPU 1: Put process  2 to run queue
	CPU 1: Dispatched process  4
Time slot  10
	CPU 0: Dispatched process  2
	CPU 2: Put process  3 to run queue
	CPU 2: Dispatched process  3
print_pgtbl: 0 - -1print_pgtbl: 0 - -1
00000000: 80000000

Time slot  11
print_pgtbl: 0 - -1
00000000: 80000000
00000300: 80000001	Loaded a process at input/proc/s3, PID: 5 PRIO: 39

libfree:205
print_pgtbl: 0 - -1
	CPU 3: Processed  1 has finished
	CPU 3: Dispatched process  5
Time slot  12
	CPU 0: Processed  2 has finished
	CPU 2: Put process  3 to run queue
	CPU 2: Dispatched process  3
print_pgtbl: 0 - -1	CPU 1: Put process  4 to run queue
	CPU 1: Dispatched process  4

print_pgtbl: 0 - -1
00000000: 80000002Time slot  13

	CPU 3: Put process  5 to run queue
	CPU 3: Dispatched process  5
	CPU 2: Put process  3 to run queue
	CPU 2: Dispatched process  3
print_pgtbl: 0 - -1
00000000: 80000002Time slot  14

	Loaded a process at input/proc/m1s, PID: 6 PRIO: 15
	CPU 1: Put process  4 to run queue
	CPU 1: Dispatched process  6
print_pgtbl: 0 - -1
print_pgtbl: 0 - -1print_pgtbl: 0 - -1
00000000: 80000002Time slot  15
	CPU 0: Dispatched process  4


	CPU 3: Put process  5 to run queue
	CPU 3: Dispatched process  5
	CPU 2: Put process  3 to run queue
	CPU 2: Dispatched process  3
print_pgtbl: 0 - -1
00000000: 80000002Time slot  16

	CPU 1: Put process  6 to run queue
	CPU 1: Dispatched process  6
libfree:205
print_pgtbl: 0 - -1	Loaded a process at input/proc/s2, PID: 7 PRIO: 120

print_pgtbl: 0 - -1Time slot  17
print_pgtbl: 0 - -1
00000000: 80000002	CPU 0: Put process  4 to run queue
	CPU 0: Dispatched process  4


	Loaded a process at input/proc/s1, PID: 8 PRIO: 0
	CPU 3: Put process  5 to run queue
	CPU 2: Put process  3 to run queue
	CPU 3: Dispatched process  8
	CPU 2: Dispatched process  5
Time slot  18
	CPU 1: Put process  6 to run queue
	CPU 1: Dispatched process  6
libfree:205
print_pgtbl: 0 - -1
libfree:205
print_pgtbl: 0 - -1Time slot  19

	CPU 0: Put process  4 to run queue
	CPU 0: Dispatched process  4
	CPU 3: Put process  8 to run queue
	CPU 3: Dispatched process  8
	CPU 2: Put process  5 to run queue
	CPU 2: Dispatched process  5
	CPU 1: Processed  6 has finished
	CPU 1: Dispatched process  7
Time slot  20
Time slot  21
	CPU 0: Put process  4 to run queue
	CPU 0: Dispatched process  4
	CPU 3: Put process  8 to run queue
	CPU 3: Dispatched process  8
	CPU 2: Put process  5 to run queue
	CPU 2: Dispatched process  5
	CPU 1: Put process  7 to run queue
	CPU 1: Dispatched process  7
Time slot  22
	CPU 2: Processed  5 has finished
	CPU 2: Dispatched process  3
print_pgtbl: 0 - -1
00000000: 80000002Time slot  23
	CPU 0: Put process  4 to run queue
	CPU 0: Dispatched process  4

	CPU 3: Put process  8 to run queue
	CPU 3: Dispatched process  8
Time slot  24
	CPU 1: Put process  7 to run queue
	CPU 1: Dispatched process  7
	CPU 3: Processed  8 has finished
	CPU 3 stopped
	CPU 2: Put process  3 to run queue
	CPU 2: Dispatched process  3
libfree:205
print_pgtbl: 0 - -1
00000000: 80000002Time slot  25
	CPU 0: Put process  4 to run queue
	CPU 0: Dispatched process  4

Time slot  26
	CPU 0: Processed  4 has finished
	CPU 0 stopped
	CPU 1: Put process  7 to run queue
	CPU 1: Dispatched process  7
	CPU 2: Processed  3 has finished
	CPU 2 stopped
Time slot  27
Time slot  28
	CPU 1: Put process  7 to run queue
	CPU 1: Dispatched process  7
Time slot  29
Time slot  30
	CPU 1: Put process  7 to run queue
	CPU 1: Dispatched process  7
Time slot  31
Time slot  32
	CPU 1: Processed  7 has finished
	CPU 1 stopped
